Workbook

Sheet Sheet2
A3: Row Labels | B3: Thực tế | C3: Hoá đơn | D3: Sum of Số tiền phải trả gửi giá | E3: Sum of Công nợ
A4: Bình Minh | B4: 1456712000 | C4: 1456712000 | D4: 0 | E4: 0
A5: VG05 | B5: 638072000 | C5: 638072000 | D5: 0 | E5: 0
A6: 4 | B6: 638072000 | C6: 638072000 | D6: 0 | E6: 0
A7: VG09 | B7: 818640000 | C7: 818640000 | D7: 0 | E7: 0
A8: 50 | B8: 818640000 | C8: 818640000 | D8: 0 | E8: 0
A9: Hoàng Quyên | B9: 9196737300 | C9: 9057734000 | D9: 3.3176885e+08 | E9: 5007026750
A10: VG05 | B10: 2059699100 | C10: 2189277200 | D10: 95983778 | E10: 6.1712165e+08
A11: 2 | B11: 490256250 | C11: 541242900 | D11: 37767889 | E11: 0
A12: 11 | B12: 477002400 | C12: 4.96179e+08 | D12: 14204889 | E12: 0
A13: 20 | B13: 475318800 | C13: 5.3473365e+08 | D13: 44011000 | E13: 0
A14: 41 | B14: 617121650 | C14: 6.1712165e+08 | D14: 0 | E14: 6.1712165e+08
A15: VG09 | B15: 1814150300 | C15: 1985624000 | D15: 1.2701756e+08 | E15: 7.801623e+08
A16: 6 | B16: 573185000 | C16: 5.607771e+08 | D16: -9191037 | E16: 0
A17: 26 | B17: 552586800 | C17: 644684600 | D17: 68220593 | E17: 0
A18: 36 | B18: 6.883785e+08 | C18: 7.801623e+08 | D18: 67988000 | E18: 7.801623e+08
A19: VG15 | B19: 2431488850 | C19: 2564864700 | D19: 98796926 | E19: 1291774700
A20: 8 | B20: 577403750 | C20: 6.170612e+08 | D20: 29375889 | E20: 0
A21: 27 | B21: 562310400 | C21: 656028800 | D21: 69421037 | E21: 0
A22: 40 | B22: 679075600 | C22: 6.790756e+08 | D22: 0 | E22: 6.790756e+08
A23: 49 | B23: 612699100 | C23: 612699100 | D23: 0 | E23: 612699100
A24: VG18 | B24: 836162200 | C24: 8.361622e+08 | D24: 0 | E24: 8.361622e+08
A25: 39 | B25: 836162200 | C25: 8.361622e+08 | D25: 0 | E25: 8.361622e+08
A26: VG36 | B26: 2055236850 | C26: 1481805900 | D26: 9970592.6 | E26: 1481805900
A27: 5 | B27: 596295700 | C27: 609756000 | D27: 9970592.6 | E27: 609756000
A28: 9 | B28: 872049900 | C28: 872049900 | D28: 0 | E28: 872049900
A29: 52 | B29: 586891250 | E29: 0
A30: Ngọc Anh | B30: 3.060805e+10 | C30: 3.006552e+10 | D30: 2.704393e+08 | E30: 6.9672101e+09
A31: VG05 | B31: 4329248010 | C31: 4361312010 | D31: 23751111 | E31: 1473967100
A32: 14 | B32: 893784000 | C32: 925848000 | D32: 23751111 | E32: 0
A33: 31 | B33: 346465800 | C33: 3.464658e+08 | D33: 0 | E33: 0
A34: 33 | B34: 603790110 | C34: 603790110 | D34: 0 | E34: 0
A35: 37 | B35: 1011241000 | C35: 1011241000 | D35: 0 | E35: 0
A36: 45 | B36: 841736700 | C36: 8.417367e+08 | D36: 0 | E36: 8.417367e+08
A37: 51 | B37: 632230400 | C37: 632230400 | D37: 0 | E37: 632230400
A38: VG09 | B38: 3879481400 | C38: 4116084200 | D38: 1.7526133e+08 | E38: 0
A39: 10 | B39: 845150400 | C39: 892103200 | D39: 34779852 | E39: 0
A40: 17 | B40: 434767500 | C40: 434767500 | D40: 0 | E40: 0
A41: 21 | B41: 915785000 | C41: 963235000 | D41: 35148148 | E41: 0
A42: 29 | B42: 995400000 | C42: 1137600000 | D42: 1.0533333e+08 | E42: 0
...

Sheet So lieu khai thac
B1: KẾT QUẢ KINH DOANH KHAI THÁC | AS1: =+IF($V1="Cty Việt Anh",$K1, "") | AT1: =+IF($V1="Cty Thành Công",$K1, "") | AU1: =+IF($V1="Cty Sông Hậu",$K1, "") | AV1: =+IF($V1="Cty Hằng Phát",$K1, "")
B2: Doanh thu | AC2: Chi phí | AT2: =+IF($V2="Cty Thành Công",$K2, "") | AU2: =+IF($V2="Cty Sông Hậu",$K2, "") | AV2: =+IF($V2="Cty Hằng Phát",$K2, "")
A3: Tháng | B3: Tên tàu | C3: Chuyến | D3: Tên hàng | E3: Ngày xếp | F3: Cảng xếp | G3: Ngày dỡ | H3: Cảng dỡ | I3: Khối lượng tính cước | J3: Thực tế (Đơn giá đã có VAT ) | K3: Thành tiền | L3: Số hóa đơn | M3: Ngày xuất hoá đơn | N3: Tiền gửi | O3: Hóa đơn (Giá chưa VAT /1.08) | P3: Thành tiền2 | Q3: VAT 8% | R3: Tổng cộng | S3: Chênh lệch sau thuế | T3: Thuế gửi | U3: Số tiền phải trả gửi giá | V3: Đơn vị | W3: Công nợ | X3: Hết tháng 14.5 | Y3: Tháng 5 | Z3: Tháng 6 | AC3: Đại lý cảng xếp | AD3: Đại lý cảng dỡ | AE3: Tàu chi cảng xếp | AF3: Tàu chi cảng dỡ | AG3: Hoa Tiêu | AH3: Tàu lai dắt | AI3: Phí cầu bến | AJ3: Tiền Bông | AK3: Dầu DO | AL3: Dầu LO | AM3: Tiền lương | AN3: Tiền VAT | AO3: Bảo hiểm | AP3: Tiền ăn uống | AQ3: Vật tư (Công ty cấp) | AR3: Vật tư (Tàu chi) | AS3: Chi phí khác | AT3: =+IF($V3="Cty Thành Công",$K3, "") | AU3: Số Ngày | AV3: Khối lượng dầu
I4: 1 | J4: 2 | K4: (3=1*2) | L4: 4 | N4: 5 | O4: 6 | P4: (7=1*6) | Q4: (8=7*8%) | R4: (9=7+8) | S4: (10=9-3) | T4: (11=10/1.08*tỉ lệ thuế gửi) | U4: (12=10-11) | AH4: =+IF(U4="Cty Ngọc Anh",J4, "") | AI4: =+IF(V4="Cty Ngọc Anh",K4, "") | AK4: =+IF($V4="Cty Hoàng Quyên",$K4, "") | AL4: =+IF($V4="Cty Hoàng Long",$K4, "") | AM4: =+IF($V4="Cty An Hưng",$K4, "") | AN4: =+IF($V4="Cty An Hưng",$K4, "") | AO4: =+IF($V4="Cty An Hưng",$K4, "") | AP4: =+IF($V4="Cty Thành Năm",$K4, "") | AQ4: =+IF($V4="Cty Tân Hoàng Đạt",$K4, "") | AR4: =+IF($V4="Cty Thái Bình Dương",$K4, "") | AS4: =+IF($V4="Cty Việt Anh",$K4, "") | AT4: =+IF($V4="Cty Thành Công",$K4, "")
A5: 12026 | B5: VG05 | C5: C1 | D5: Cát | E5: 46018 | F5: Vĩnh Xương | G5: 46024 | H5: Đà Nẵng | I5: 3922.05 | J5: 125000 | K5: =I5*J5 -> 490256250 | L5: 2 | M5: 7/1 | N5: 13000 | O5: =+(J5+N5)/1.08 -> 127777.78 | P5: =I5*O5 -> 5.0115083e+08 | Q5: =P5*0.08 -> 40092067 | R5: =(+P5+Q5) -> 541242900 | S5: =R5-K5 -> 50986650 | T5: =S5/1.08*28% -> 13218761 | U5: =S5-T5 -> 37767889 | V5: Hoàng Quyên | W5: =+Table2[[#This Row],[Thành tiền]]+Table2[[#This Row],[Chênh lệch sau thuế]]-SUM(X5:Z5) -> 0 | X5: 541242900 | AC5: 9312140 | AE5: 2500000 | AF5: 15699000 | AJ5: 11137000 | AK5: 310565000 | AM5: 223811168 | AN5: =+K5*0.08 -> 39220500 | AO5: 10069583 | AP5: 46980000 | AQ5: 14888000 | AR5: 4706000 | AT5: =+SUM(AC5:AS5) -> 688888391 | AU5: =+G5-E5 -> 6 | AV5: 105
A6: 12026 | B6: VG05 | C6: C2 | D6: Clinker | E6: =+G5+1 -> 46025 | F6: Chân Mây | G6: 46035 | H6: Hậu Giang | I6: 3987.95 | J6: 160000 | K6: =I6*J6 -> 638072000 | L6: 4 | M6: 16/1 | N6: 0 | O6: =+(J6+N6)/1.08 -> 148148.15 | P6: =I6*O6 -> 5.9080741e+08 | Q6: =P6*0.08 -> 47264593 | R6: =(+P6+Q6) -> 638072000 | S6: =R6-K6 -> 0 | T6: =S6/1.08*28% -> 0 | U6: =S6-T6 -> 0 | V6: Bình Minh | W6: =+Table2[[#This Row],[Tổng cộng]]-SUM(X6:Z6) -> 0 | X6: 638072000 | AD6: 8893400 | AE6: 17406000 | AF6: 2000000 | AI6: =300000*1.5*11*2 -> 9900000 | AJ6: 7425000 | AK6: 393915500 | AM6: 15712000 | AN6: =+K6*0.08 -> 51045760 | AT6: =+SUM(AC6:AS6) -> 506297660 | AU6: =+G6-E6 -> 10 | AV6: 87
A7: 12026 | B7: VG05 | C7: C3 | D7: Cát | E7: =+G6+1 -> 46036 | F7: Vĩnh Xương | G7: 46046 | H7: Đà Nẵng | I7: 3975.02 | J7: 120000 | K7: =I7*J7 -> 477002400 | L7: 11 | M7: 28/1 | N7: 4824.2776 | O7: =+(J7+N7)/1.08 -> 115578.03 | P7: =I7*O7 -> 4.59425e+08 | Q7: =P7*0.08 -> 36754000 | R7: =(+P7+Q7) -> 4.96179e+08 | S7: =R7-K7 -> 19176600 | T7: =S7/1.08*28% -> 4971711.1 | U7: =S7-T7 -> 14204889 | V7: Hoàng Quyên | W7: =+Table2[[#This Row],[Tổng cộng]]-SUM(X7:Z7) -> 0 | X7: 4.96179e+08 | AC7: 9531480 | AE7: 2500000 | AF7: 14248000 | AJ7: 11137000 | AN7: =+K7*0.08 -> 38160192 | AT7: =+SUM(AC7:AS7) -> 75576672 | AU7: =+G7-E7 -> 10 | AV7: 127
A8: 12026 | B8: VG05 | C8: C4 | D8: Xỉ | E8: =+G7+1 -> 46047 | F8: Sơn Dương | G8: 46054 | H8: Cần Thơ | I8: 4008 | J8: 223000 | K8: =I8*J8 -> 893784000 | L8: 14 | N8: 8000 | O8: =+(J8+N8)/1.08 -> 213888.89 | P8: =I8*O8 -> 8.5726667e+08 | Q8: =P8*0.08 -> 68581333 | R8: =(+P8+Q8) -> 925848000 | S8: =R8-K8 -> 32064000 | T8: =S8/1.08*28% -> 8312888.9 | U8: =S8-T8 -> 23751111 | V8: Ngọc Anh | W8: =+Table2[[#This Row],[Tổng cộng]]-SUM(X8:Z8) -> 0 | X8: 925848000 | AC8: 41658617 | AD8: 9820610 | AE8: 2800000 | AF8: 3100000 | AJ8: 7425000 | AL8: =+IF($V8="Cty Hoàng Long",$K8, "") | AN8: =+K8*0.08 -> 71502720 | AS8: =+IF($V8="Cty Việt Anh",$K8, "") | AT8: =+SUM(AC8:AS8) -> 136306947 | AU8: =+G8-E8 -> 7 | AV8: 125
A9: 22026 | B9: VG05 | C9: C5 | D9: Cát | E9: =+G8+1 -> 46055 | F9: Cần Thơ | G9: 46066 | H9: Đà Nẵng | I9: 3960.99 | J9: 120000 | K9: =I9*J9 -> 475318800 | L9: 20 | N9: 15000 | O9: =+(J9+N9)/1.08 -> 125000 | P9: =I9*O9 -> 4.9512375e+08 | Q9: =P9*0.08 -> 39609900 | R9: =(+P9+Q9) -> 5.3473365e+08 | S9: =R9-K9 -> 59414850 | T9: =S9/1.08*28% -> 15403850 | U9: =S9-T9 -> 44011000 | V9: Hoàng Quyên | W9: =+Table2[[#This Row],[Tổng cộng]]-SUM(X9:Z9) -> 0 | X9: 5.3473365e+08 | AC9: =9122710+33035 -> 9155745 | AE9: 2500000 | AF9: 23647000 | AJ9: 11137000 | AL9: =+IF($V9="Cty Hoàng Long",$K9, "") | AM9: 223811168 | AN9: =+K9*0.08 -> 38025504 | AO9: 10069583 | AP9: 37710000 | AQ9: 41517140 | AR9: 5565000 | AS9: =+IF($V9="Cty Việt Anh",$K9, "") | AT9: =+SUM(AC9:AS9) -> 403138140 | AU9: =+G9-E9 -> 11 | AV9: =+IF($V9="Cty Hằng Phát",$K9, "")
A10: 22026 | B10: VG05 | C10: C6 | D10: Cliker | E10: =+G9+1 -> 46067 | F10: Hòn La | G10: 46087 | H10: Cần Thơ | I10: 3999.6 | J10: 200000 | K10: =I10*J10 -> 799920000 | L10: 25 | N10: 17000 | O10: =+(J10+N10)/1.08 -> 200925.93 | P10: =I10*O10 -> 8.0362333e+08 | Q10: =P10*0.08 -> 64289867 | R10: =(+P10+Q10) -> 867913200 | S10: =R10-K10 -> 67993200 | T10: =S10/1.08*28% -> 17627867 | U10: =S10-T10 -> 50365333 | V10: Thái Bình Dương | W10: =+Table2[[#This Row],[Tổng cộng]]-SUM(X10:Z10) -> 0 | X10: 867913200 | AC10: 11682336 | AD10: 9451720 | AN10: =+K10*0.08 -> 63993600 | AT10: =+SUM(AC10:AS10) -> 85127656 | AU10: =+G10-E10 -> 20
A11: 32026 | B11: VG05 | C11: C7 | D11: Quặng | E11: =+G10+1 -> 46088 | F11: Vĩnh Xương | G11: 46104 | H11: Hải Phòng | I11: 3998.61 | J11: 151000 | K11: =I11*J11 -> 603790110 | L11: 33 | O11: =+(J11+N11)/1.08 -> 139814.81 | P11: =I11*O11 -> 5.5906492e+08 | Q11: =P11*0.08 -> 44725193 | R11: =(+P11+Q11) -> 603790110 | S11: =R11-K11 -> 0 | T11: =S11/1.08*28% -> 0 | U11: =S11-T11 -> 0 | V11: Ngọc Anh | W11: =+Table2[[#This Row],[Tổng cộng]]-SUM(X11:Z11) -> 0 | X11: 603790110 | AC11: 9860490 | AD11: 8845900 | AN11: =+K11*0.08 -> 48303209 | AT11: =+SUM(AC11:AS11) -> 67009599 | AU11: =+G11-E11 -> 16
A12: 32026 | B12: VG05 | C12: C8 | D12: Than | E12: =+G11+1 -> 46105 | F12: Quảng Ninh | G12: 46110 | H12: Nghi Sơn | I12: 3849.62 | J12: 90000 | K12: =I12*J12 -> 346465800 | L12: 31 | O12: =+(J12+N12)/1.08 -> 83333.333 | P12: =I12*O12 -> 3.2080167e+08 | Q12: =P12*0.08 -> 25664133 | R12: =(+P12+Q12) -> 3.464658e+08 | S12: =R12-K12 -> 0 | T12: =S12/1.08*28% -> 0 | U12: =S12-T12 -> 0 | V12: Ngọc Anh | W12: =+Table2[[#This Row],[Tổng cộng]]-SUM(X12:Z12) -> 0 | X12: 3.464658e+08 | AN12: =+K12*0.08 -> 27717264 | AT12: =+SUM(AC12:AS12) -> 27717264 | AU12: =+G12-E12 -> 5
A13: 42026 | B13: VG05 | C13: C9 | D13: Xỉ | E13: =+G12+1 -> 46111 | F13: Sơn Dương | G13: 46118 | H13: Cần Thơ | I13: 3997 | J13: 253000 | K13: =I13*J13 -> 1011241000 | L13: 37 | O13: =+(J13+N13)/1.08 -> 234259.26 | P13: =I13*O13 -> 9.3633426e+08 | Q13: =P13*0.08 -> 74906741 | R13: =(+P13+Q13) -> 1011241000 | S13: =R13-K13 -> 0 | T13: =S13/1.08*28% -> 0 | U13: =S13-T13 -> 0 | V13: Ngọc Anh | W13: =+Table2[[#This Row],[Tổng cộng]]-SUM(X13:Z13) -> 0 | X13: 1011241000 | AD13: 10292000 | AN13: =+K13*0.08 -> 80899280 | AT13: =+SUM(AC13:AS13) -> 91191280 | AU13: =+G13-E13 -> 7
A14: 42026 | B14: VG05 | C14: C10 | D14: Cát | E14: =+G13+1 -> 46119 | F14: Vĩnh Xương | G14: 46127 | H14: Đà Nẵng | I14: 3981.43 | J14: 155000 | K14: =I14*J14 -> 617121650 | L14: 41 | O14: =+(J14+N14)/1.08 -> 143518.52 | P14: =I14*O14 -> 5.7140894e+08 | Q14: =P14*0.08 -> 45712715 | R14: =(+P14+Q14) -> 6.1712165e+08 | S14: =R14-K14 -> 0 | T14: =S14/1.08*28% -> 0 | U14: =S14-T14 -> 0 | V14: Hoàng Quyên | W14: =+Table2[[#This Row],[Tổng cộng]]-SUM(X14:Z14) -> 6.1712165e+08 | AC14: =7000126-276 -> 6999850 | AN14: =+K14*0.08 -> 49369732
A15: 42026 | B15: VG05 | C15: C11 | D15: Clinker | E15: =+G14+1 -> 46128 | F15: Chân Mây | G15: 46136 | H15: Hậu Giang | I15: 4008.27 | J15: 210000 | K15: =I15*J15 -> 841736700 | L15: 45 | O15: =+(J15+N15)/1.08 -> 194444.44 | P15: =I15*O15 -> 7.7938583e+08 | Q15: =P15*0.08 -> 62350867 | R15: =(+P15+Q15) -> 8.417367e+08 | S15: =R15-K15 -> 0 | T15: =S15/1.08*28% -> 0 | U15: =S15-T15 -> 0 | V15: Ngọc Anh | W15: =+Table2[[#This Row],[Tổng cộng]]-SUM(X15:Z15) -> 8.417367e+08
A16: 42026 | B16: VG05 | C16: C12 | D16: Quặng | E16: =+G15+1 -> 46137 | F16: Vĩnh Xương | G16: 46150 | H16: Vật Cách | I16: 3951.44 | J16: 160000 | K16: =I16*J16 -> 632230400 | L16: 51 | O16: =+(J16+N16)/1.08 -> 148148.15 | P16: =I16*O16 -> 5.8539852e+08 | Q16: =P16*0.08 -> 46831881 | R16: =(+P16+Q16) -> 632230400 | S16: =R16-K16 -> 0 | T16: =S16/1.08*28% -> 0 | U16: =S16-T16 -> 0 | V16: Ngọc Anh | W16: =+Table2[[#This Row],[Tổng cộng]]-SUM(X16:Z16) -> 632230400
W17: =+Table2[[#This Row],[Tổng cộng]]-SUM(X17:Z17) -> 0 | X17: 0
W18: =+Table2[[#This Row],[Tổng cộng]]-SUM(X18:Z18) -> 0 | X18: 0 | AN18: =+K18*0.08 -> 0 | AT18: =+SUM(AC18:AS18) -> 0 | AU18: =+G18-E18 -> 0
A19: 12026 | B19: VG09 | C19: C1 | D19: Cát | E19: 46021 | F19: Vĩnh Xương | G19: 46037 | H19: Đà Nẵng | I19: 4585.48 | J19: 125000 | K19: =I19*J19 -> 573185000 | L19: 6 | M19: 20/1 | N19: -2705.9108 | O19: =+(J19+N19)/1.08 -> 113235.27 | P19: =I19*O19 -> 5.1923806e+08 | Q19: =P19*0.08 -> 41539044 | R19: =(+P19+Q19) -> 5.607771e+08 | S19: =R19-K19 -> -12407900 | T19: =S19/1.08*28% -> -3216863 | U19: =S19-T19 -> -9191037 | V19: Hoàng Quyên | W19: =+Table2[[#This Row],[Tổng cộng]]-SUM(X19:Z19) -> 0 | X19: 5.607771e+08 | AC19: 57146836 | AE19: 4180000 | AF19: 18961000 | AG19: 9979200 | AI19: 7779048 | AJ19: 11132000 | AK19: 736178300 | AM19: 2.547827e+08 | AN19: =+K19*0.08 -> 45854800 | AO19: 12061667 | AP19: 53580000 | AR19: 1316000 | AT19: =+SUM(AC19:AS19) -> 1.2129516e+09 | AU19: =+G19-E19 -> 16
A20: 12026 | B20: VG09 | C20: C2 | D20: Xỉ | E20: =+G19+1 -> 46038 | F20: Sơn Dương | G20: 46046 | H20: HCM | I20: 4695.28 | J20: 180000 | K20: =I20*J20 -> 845150400 | L20: 10 | M20: 26/1 | N20: 10000 | O20: =+(J20+N20)/1.08 -> 175925.93 | P20: =I20*O20 -> 8.2602148e+08 | Q20: =P20*0.08 -> 66081719 | R20: =(+P20+Q20) -> 892103200 | S20: =R20-K20 -> 46952800 | T20: =S20/1.08*28% -> 12172948 | U20: =S20-T20 -> 34779852 | V20: Ngọc Anh | W20: =+Table2[[#This Row],[Tổng cộng]]-SUM(X20:Z20) -> 0 | X20: 892103200 | AC20: 44012220 | AD20: 32791040 | AE20: 5800000 | AF20: 7300000 | AJ20: 5775000 | AM20: 22816000 | AN20: =+K20*0.08 -> 67612032 | AT20: =+SUM(AC20:AS20) -> 186106292 | AU20: =+G20-E20 -> 8
A21: 22026 | B21: VG09 | C21: C3 | D21: Tro ẩm | E21: =+G20+1 -> 46047 | F21: Vĩnh Tân | G21: 46058 | H21: Nghi Sơn | I21: 4576.5 | J21: 95000 | K21: =I21*J21 -> 434767500 | L21: 17 | O21: =+(J21+N21)/1.08 -> 87962.963 | P21: =I21*O21 -> 402562500 | Q21: =P21*0.08 -> 32205000 | R21: =(+P21+Q21) -> 434767500 | S21: =R21-K21 -> 0 | T21: =S21/1.08*28% -> 0 | U21: =S21-T21 -> 0 | V21: Ngọc Anh | W21: =+Table2[[#This Row],[Tổng cộng]]-SUM(X21:Z21) -> 0 | X21: 434767500 | AC21: 43024312 | AE21: 7400000 | AF21: 12570000 | AJ21: 9900000 | AK21: 355195500 | AM21: 2.547827e+08 | AN21: =+K21*0.08 -> 34781400 | AO21: 12061667 | AP21: 22817000 | AQ21: 7175640 | AR21: 2995000 | AT21: =+SUM(AC21:AS21) -> 7.6270322e+08 | AU21: =+G21-E21 -> 11
A22: 22026 | B22: VG09 | C22: C4 | D22: Xỉ | E22: =+G21+1 -> 46059 | F22: Sơn Dương | G22: 46080 | H22: Hậu Giang | I22: 4745 | J22: 193000 | K22: =I22*J22 -> 915785000 | L22: 21 | N22: 10000 | O22: =+(J22+N22)/1.08 -> 187962.96 | P22: =I22*O22 -> 8.9188426e+08 | Q22: =P22*0.08 -> 71350741 | R22: =(+P22+Q22) -> 963235000 | S22: =R22-K22 -> 47450000 | T22: =S22/1.08*28% -> 12301852 | U22: =S22-T22 -> 35148148 | V22: Ngọc Anh | W22: =+Table2[[#This Row],[Tổng cộng]]-SUM(X22:Z22) -> 0 | X22: 963235000 | AC22: 43593515 | AD22: 36923510 | AE22: =2800000+27200000 -> 30000000 | AM22: 22816000 | AN22: =+K22*0.08 -> 73262800 | AT22: =+SUM(AC22:AS22) -> 206595825 | AU22: =+G22-E22 -> 21
A23: 32026 | B23: VG09 | C23: C5 | D23: Cát | E23: =+G22+1 -> 46081 | F23: Vĩnh Xương | G23: 46096 | H23: Đà Nẵng | I23: 4604.89 | J23: 120000 | K23: =I23*J23 -> 552586800 | L23: 26 | N23: 20000 | O23: =+(J23+N23)/1.08 -> 129629.63 | P23: =I23*O23 -> 5.9693019e+08 | Q23: =P23*0.08 -> 47754415 | R23: =(+P23+Q23) -> 644684600 | S23: =R23-K23 -> 92097800 | T23: =S23/1.08*28% -> 23877207 | U23: =S23-T23 -> 68220593 | V23: Hoàng Quyên | W23: =+Table2[[#This Row],[Tổng cộng]]-SUM(X23:Z23) -> 0 | X23: 644684600 | AC23: 56025556 | AN23: =+K23*0.08 -> 44206944 | AT23: =+SUM(AC23:AS23) -> 100232500 | AU23: =+G23-E23 -> 15
A24: 32026 | B24: VG09 | C24: C6 | D24: Xỉ | E24: =+G23+1 -> 46097 | F24: Sơn Dương | G24: 46107 | H24: XM Tây Đô | I24: 4740 | J24: 210000 | K24: =I24*J24 -> 995400000 | L24: 29 | N24: 30000 | O24: =+(J24+N24)/1.08 -> 222222.22 | P24: =I24*O24 -> 1.0533333e+09 | Q24: =P24*0.08 -> 84266667 | R24: =(+P24+Q24) -> 1137600000 | S24: =R24-K24 -> 142200000 | T24: =S24/1.08*28% -> 36866667 | U24: =S24-T24 -> 1.0533333e+08 | V24: Ngọc Anh | W24: =+Table2[[#This Row],[Tổng cộng]]-SUM(X24:Z24) -> 0 | X24: 1137600000 | AC24: 43126475 | AD24: 21699456 | AN24: =+K24*0.08 -> 79632000 | AT24: =+SUM(AC24:AS24) -> 144457931 | AU24: =+G24-E24 -> 10
A25: 42026 | B25: VG09 | C25: C7 | D25: Cát | E25: =+G24+1 -> 46108 | F25: Vĩnh Xương | G25: 46116 | H25: Đà Nẵng | I25: 4589.19 | J25: 150000 | K25: =I25*J25 -> 6.883785e+08 | L25: 36 | N25: 20000 | O25: =+(J25+N25)/1.08 -> 157407.41 | P25: =I25*O25 -> 7.223725e+08 | Q25: =P25*0.08 -> 57789800 | R25: =(+P25+Q25) -> 7.801623e+08 | S25: =R25-K25 -> 91783800 | T25: =S25/1.08*28% -> 23795800 | U25: =S25-T25 -> 67988000 | V25: Hoàng Quyên | W25: =+Table2[[#This Row],[Tổng cộng]]-SUM(X25:Z25) -> 7.801623e+08 | AC25: 56448916 | AN25: =+K25*0.08 -> 55070280 | AU25: =+G25-E25 -> 8
A26: 42026 | B26: VG09 | C26: C8 | D26: Xỉ | E26: =+G25+1 -> 46117 | F26: Sơn Dương | G26: 46130 | H26: Hậu Giang | I26: 4589.19 | J26: 150000 | K26: =I26*J26 -> 6.883785e+08 | L26: 42 | O26: =+(J26+N26)/1.08 -> 138888.89 | P26: =I26*O26 -> 6.373875e+08 | Q26: =P26*0.08 -> 50991000 | R26: =(+P26+Q26) -> 6.883785e+08 | S26: =R26-K26 -> 0 | T26: =S26/1.08*28% -> 0 | U26: =S26-T26 -> 0 | V26: Ngọc Anh | W26: =+Table2[[#This Row],[Tổng cộng]]-SUM(X26:Z26) -> 0 | X26: 6.883785e+08
A27: 42026 | B27: VG09 | C27: C9 | D27: Cát | E27: =+G26+1 -> 46131 | F27: Sơn Dương | G27: 46148 | H27: Huy Văn | I27: 1 | J27: 818640000 | K27: =I27*J27 -> 818640000 | L27: 50 | O27: =+(J27+N27)/1.08 -> 758000000 | P27: =I27*O27 -> 758000000 | Q27: =P27*0.08 -> 60640000 | R27: =(+P27+Q27) -> 818640000 | S27: =R27-K27 -> 0 | T27: =S27/1.08*28% -> 0 | U27: =S27-T27 -> 0 | V27: Bình Minh | W27: =+Table2[[#This Row],[Tổng cộng]]-SUM(X27:Z27) -> 0 | X27: 818640000
W28: =+Table2[[#This Row],[Tổng cộng]]-SUM(X28:Z28) -> 0 | X28: 0
W29: =+Table2[[#This Row],[Tổng cộng]]-SUM(X29:Z29) -> 0 | X29: 0 | AT29: =+SUM(AC29:AS29) -> 0 | AU29: =+G29-E29 -> 0
A30: 12026 | B30: VG15 | C30: C1 | D30: Xỉ | E30: 46022 | F30: Sơn Dương | G30: 46028 | H30: Hậu Giang | I30: 4814 | J30: 183000 | K30: =I30*J30 -> 880962000 | L30: 3 | M30: 7/1 | N30: 10000 | O30: =+(J30+N30)/1.08 -> 178703.7 | P30: =I30*O30 -> 8.6027963e+08 | Q30: =P30*0.08 -> 68822370 | R30: =(+P30+Q30) -> 9.29102e+08 | S30: =R30-K30 -> 48140000 | T30: =S30/1.08*28% -> 12480741 | U30: =S30-T30 -> 35659259 | V30: Ngọc Anh | W30: =+Table2[[#This Row],[Tổng cộng]]-SUM(X30:Z30) -> 0 | X30: 9.29102e+08 | AC30: 44773738 | AD30: 35337690 | AF30: 4340000 | AJ30: 7425000 | AK30: 377484800 | AL30: =+IF($V30="Cty Hoàng Long",$K30, "") | AM30: 255338967 | AN30: =+K30*0.08 -> 70476960 | AO30: 11511042 | AP30: 44994000 | AQ30: 79100000 | AR30: 4855000 | AS30: =+IF($V30="Cty Việt Anh",$K30, "") | AT30: =+SUM(AC30:AS30) -> 935637197 | AU30: =+G30-E30 -> 6 | AV30: =+IF($V30="Cty Hằng Phát",$K30, "")
A31: 12026 | B31: VG15 | C31: C2 | D31: Cát | E31: =+G30+1 -> 46029 | F31: Vĩnh Xương | G31: 46041 | H31: Đà Nẵng | I31: 4619.23 | J31: 125000 | K31: =I31*J31 -> 577403750 | L31: 8 | M31: 21/1 | N31: 8585.2945 | O31: =+(J31+N31)/1.08 -> 123690.09 | P31: =I31*O31 -> 5.7135296e+08 | Q31: =P31*0.08 -> 45708237 | R31: =(+P31+Q31) -> 6.170612e+08 | S31: =R31-K31 -> 39657450 | T31: =S31/1.08*28% -> 10281561 | U31: =S31-T31 -> 29375889 | V31: Hoàng Quyên | W31: =+Table2[[#This Row],[Tổng cộng]]-SUM(X31:Z31) -> 0 | X31: 6.170612e+08 | AC31: 55058278 | AE31: 4470000 | AF31: 19639000 | AJ31: 11132000 | AL31: =+IF($V31="Cty Hoàng Long",$K31, "") | AM31: 20000000 | AN31: =+K31*0.08 -> 46192300 | AS31: =+IF($V31="Cty Việt Anh",$K31, "") | AT31: =+SUM(AC31:AS31) -> 156491578 | AU31: =+G31-E31 -> 12 | AV31: =+IF($V31="Cty Hằng Phát",$K31, "")
A32: 12026 | B32: VG15 | C32: C3 | D32: Xỉ | E32: =+G31+1 -> 46042 | F32: Sơn Dương | G32: 46056 | H32: Hậu Giang | I32: 4810 | J32: 193000 | K32: =I32*J32 -> 928330000 | L32: 12 | N32: 10000 | O32: =+(J32+N32)/1.08 -> 187962.96 | P32: =I32*O32 -> 9.0410185e+08 | Q32: =P32*0.08 -> 72328148 | R32: =(+P32+Q32) -> 976430000 | S32: =R32-K32 -> 48100000 | T32: =S32/1.08*28% -> 12470370 | U32: =S32-T32 -> 35629630 | V32: Ngọc Anh | W32: =+Table2[[#This Row],[Tổng cộng]]-SUM(X32:Z32) -> 0 | X32: 976430000 | AC32: 44454445 | AD32: 38432391 | AE32: 2800000 | AF32: 2490000 | AJ32: 7425000 | AM32: 45800000 | AN32: =+K32*0.08 -> 74266400 | AT32: =+SUM(AC32:AS32) -> 215668236 | AU32: =+G32-E32 -> 14
A33: 22026 | B33: VG15 | C33: C4 | D33: Quặng | E33: =+G32+1 -> 46057 | F33: Vĩnh Xương | G33: 46076 | H33: Hải Phòng | I33: 4657.68 | J33: 145000 | K33: =I33*J33 -> 675363600 | L33: 18 | O33: =+(J33+N33)/1.08 -> 134259.26 | P33: =I33*O33 -> 6.2533667e+08 | Q33: =P33*0.08 -> 50026933 | R33: =(+P33+Q33) -> 675363600 | S33: =R33-K33 -> 0 | T33: =S33/1.08*28% -> 0 | U33: =S33-T33 -> 0 | V33: Thái Bình Dương | W33: =+Table2[[#This Row],[Tổng cộng]]-SUM(X33:Z33) -> 0 | X33: 675363600 | AC33: 56147548 | AD33: 27619385 | AE33: 11195000 | AF33: =11375000+6820000 -> 18195000 | AJ33: 11000000 | AK33: 563635700 | AM33: 255338967 | AN33: =+K33*0.08 -> 54029088 | AO33: 11511042 | AP33: 40320000 | AT33: =+SUM(AC33:AS33) -> 1048991730 | AU33: =+G33-E33 -> 19
A34: 22026 | B34: VG15 | C34: C5 | D34: Xỉ | E34: =+G33+1 -> 46077 | F34: Sơn Dương | G34: 46088 | H34: HCM | I34: 4796 | J34: 193000 | K34: =I34*J34 -> 925628000 | L34: 23 | O34: =+(J34+N34)/1.08 -> 178703.7 | P34: =I34*O34 -> 8.5706296e+08 | Q34: =P34*0.08 -> 68565037 | R34: =(+P34+Q34) -> 9.25628e+08 | S34: =R34-K34 -> 0 | T34: =S34/1.08*28% -> 0 | U34: =S34-T34 -> 0 | V34: Ngọc Anh | W34: =+Table2[[#This Row],[Tổng cộng]]-SUM(X34:Z34) -> 0 | X34: 9.25628e+08 | AC34: =11979485+42947980 -> 54927465 | AD34: 35108518 | AE34: 1800000 | AN34: =+K34*0.08 -> 74050240 | AT34: =+SUM(AC34:AS34) -> 165886223 | AU34: =+G34-E34 -> 11
A35: 32026 | B35: VG15 | C35: C6 | D35: Cát | E35: =+G34+1 -> 46089 | F35: Vĩnh Xương | G35: 46101 | H35: Đà Nẵng | I35: 4685.92 | J35: 120000 | K35: =I35*J35 -> 562310400 | L35: 27 | N35: 20000 | O35: =+(J35+N35)/1.08 -> 129629.63 | P35: =I35*O35 -> 6.0743407e+08 | Q35: =P35*0.08 -> 48594726 | R35: =(+P35+Q35) -> 656028800 | S35: =R35-K35 -> 93718400 | T35: =S35/1.08*28% -> 24297363 | U35: =S35-T35 -> 69421037 | V35: Hoàng Quyên | W35: =+Table2[[#This Row],[Tổng cộng]]-SUM(X35:Z35) -> 0 | X35: 656028800 | AC35: 54802633 | AN35: =+K35*0.08 -> 44984832 | AT35: =+SUM(AC35:AS35) -> 99787465 | AU35: =+G35-E35 -> 12
A36: 32026 | B36: VG15 | C36: C7 | D36: Clkiner | E36: =+G35+1 -> 46102 | F36: Chân Mây | G36: 46113 | H36: Hậu Giang | I36: 4750.84 | J36: 235000 | K36: =I36*J36 -> 1116447400 | L36: 34 | O36: =+(J36+N36)/1.08 -> 217592.59 | P36: =I36*O36 -> 1.0337476e+09 | Q36: =P36*0.08 -> 82699807 | R36: =(+P36+Q36) -> 1116447400 | S36: =R36-K36 -> 0 | T36: =S36/1.08*28% -> 0 | U36: =S36-T36 -> 0 | V36: Ngọc Anh | W36: =+Table2[[#This Row],[Tổng cộng]]-SUM(X36:Z36) -> 0 | X36: 1116447400 | AD36: 37347457 | AN36: =+K36*0.08 -> 89315792 | AT36: =+SUM(AC36:AS36) -> 126663249 | AU36: =+G36-E36 -> 11
A37: 42026 | B37: VG15 | C37: C8 | D37: Cát | E37: =+G36+1 -> 46114 | F37: Vĩnh Xương | G37: 46123 | H37: Đà Nẵng | I37: 4683.28 | J37: 145000 | K37: =I37*J37 -> 679075600 | L37: 40 | O37: =+(J37+N37)/1.08 -> 134259.26 | P37: =I37*O37 -> 6.287737e+08 | Q37: =P37*0.08 -> 50301896 | R37: =(+P37+Q37) -> 6.790756e+08 | S37: =R37-K37 -> 0 | T37: =S37/1.08*28% -> 0 | U37: =S37-T37 -> 0 | V37: Hoàng Quyên | W37: =+Table2[[#This Row],[Tổng cộng]]-SUM(X37:Z37) -> 6.790756e+08 | AC37: 54487716 | AN37: =+K37*0.08 -> 54326048 | AU37: =+G37-E37 -> 9
A38: 42026 | B38: VG15 | C38: C9 | D38: Xỉ | E38: =+G37+1 -> 46124 | F38: Sơn Dương | G38: 46134 | H38: Hậu Giang | I38: 4795 | J38: 253000 | K38: =I38*J38 -> 1213135000 | L38: 44 | O38: =+(J38+N38)/1.08 -> 234259.26 | P38: =I38*O38 -> 1.1232731e+09 | Q38: =P38*0.08 -> 89861852 | R38: =(+P38+Q38) -> 1213135000 | S38: =R38-K38 -> 0 | T38: =S38/1.08*28% -> 0 | U38: =S38-T38 -> 0 | V38: Ngọc Anh | W38: =+Table2[[#This Row],[Tổng cộng]]-SUM(X38:Z38) -> 1213135000
A39: 42026 | B39: VG15 | C39: C10 | D39: Cát | E39: =+G38+1 -> 46135 | F39: Vĩnh Xương | G39: 46145 | H39: Đà Nẵng | I39: 4713.07 | J39: 130000 | K39: =I39*J39 -> 612699100 | L39: 49 | O39: =+(J39+N39)/1.08 -> 120370.37 | P39: =I39*O39 -> 5.6731398e+08 | Q39: =P39*0.08 -> 45385119 | R39: =(+P39+Q39) -> 612699100 | S39: =R39-K39 -> 0 | T39: =S39/1.08*28% -> 0 | U39: =S39-T39 -> 0 | V39: Hoàng Quyên | W39: =+Table2[[#This Row],[Tổng cộng]]-SUM(X39:Z39) -> 612699100
W40: =+Table2[[#This Row],[Tổng cộng]]-SUM(X40:Z40) -> 0 | X40: 0 | AT40: =+SUM(AC40:AS40) -> 0 | AU40: =+G40-E40 -> 0
...

Sheet Sheet1
A1: Tàu | B1: Trọng tải | C1: Tiền ăn | D1: Tiền lương | E1: Tiền bảo hiểm | F1: Dầu Do (lit/h) | G1: Dầu LO
A2: VG05 | B2: 4000 | C2: 48500000 | D2: 209633000 | E2: 10069583 | F2: 95 | H2: =+E2*3 -> 30208749
A3: VG09 | B3: 4700 | C3: 41180000 | D3: 235647000 | E3: 12061667 | F3: 110 | H3: =+E3*3 -> 36185001
A4: VG15 | B4: 4700 | C4: 40680000 | D4: 203300000 | E4: 11511042 | F4: 100 | H4: =+E4*3 -> 34533126
A5: VG18 | B5: 8100 | C5: 50000000 | D5: 230000000 | E5: =280000000/12 -> 23333333 | F5: 204 | H5: =+E5*3 -> 70000000 | I5: =139122/6 -> 23187
A6: VG36 | B6: 4800 | C6: 42545000 | D6: 207122000 | E6: 13653750 | F6: 130 | H6: =+E6*3 -> 40961250
A10: Cảng | B10: Đại lý | C10: Tàu chi | D10: Hoa tiêu | E10: Tổng | H10: Tàu | J10: VG36 | K10: Thực tế | M10: Tàu | O10: VG18 | P10: Thực tế | R10: Tàu | T10: VG18 | U10: Thực tế
A11: 0 | B11: 0 | H11: Trọng tải | J11: =INDEX($B$2:$B$6, MATCH($J$10, $A$2:$A$6, 0)) -> 4800 | K11: 4587 | M11: Trọng tải | O11: =INDEX($B$2:$B$6, MATCH($J$10, $A$2:$A$6, 0)) -> 4800 | R11: Trọng tải | T11: =INDEX($B$2:$B$6, MATCH($J$10, $A$2:$A$6, 0)) -> 4800
A12: Quảng Ninh | B12: 35000000 | H12: Đơn giá | J12: 130000 | M12: Đơn giá | O12: 180000 | R12: Đơn giá | T12: 118000
A13: Hải Phòng | B13: 35000000 | H13: Doanh thu có VAT | J13: =+J12*MIN(K11,J11) -> 596310000 | K13: Số giờ chạy biển | M13: Doanh thu có VAT | O13: =+O12*MIN(P11,O11) -> 864000000 | P13: Số giờ chạy biển | R13: Doanh thu có VAT | T13: =+T12*MIN(U11,T11) -> 566400000 | U13: Số giờ chạy biển
A14: Huy Văn HD | C14: 30000000 | H14: Số ngày | J14: 11 | K14: 108 | M14: Số ngày | O14: 10 | P14: 96 | R14: Số ngày | T14: 12 | U14: 116
A15: Nghi Sơn | C15: 40000000 | H15: Tiền ăn, lương, bảo hiểm | J15: =SUM(INDEX($C$2:$E$6,MATCH($J$10,$A$2:$A$6,0),0))/30*J14 -> 96550942 | M15: Tiền ăn, lương, bảo hiểm | O15: =SUM(INDEX($C$2:$E$6,MATCH($O$10,$A$2:$A$6,0),0))/30*O14 -> 1.0111111e+08 | R15: Tiền ăn, lương, bảo hiểm | T15: =SUM(INDEX($C$2:$E$6,MATCH($O$10,$A$2:$A$6,0),0))/30*T14 -> 1.2133333e+08
A16: Nghi Thiết | C16: 45000000
A17: Cửa Lò | C17: 38000000 | H17: Chi phí cảng xếp | I17: Vĩnh Xương | J17: =SUM(INDEX($B$11:$D$46,MATCH($I$17,$A$11:$A$46,0),0)) -> 68550000 | M17: Chi phí cảng xếp | N17: 0 | O17: =SUM(INDEX($B$11:$D$46,MATCH(N17,$A$11:$A$46,0),0)) -> 0 | P17: =26000000+6500000+5500000 -> 38000000 | R17: Chi phí cảng xếp | S17: 0 | T17: =SUM(INDEX($B$11:$D$46,MATCH(S17,$A$11:$A$46,0),0)) -> 0 | U17: =26000000+6500000+5500000 -> 38000000
A18: Vũng Áng | B18: 40000000 | H18: Chi phí cảng dỡ | I18: Đà Nẵng | J18: =SUM(INDEX($B$11:$D$46,MATCH($I$18,$A$11:$A$46,0),0)) -> 32000000 | M18: Chi phí cảng dỡ | N18: 0 | O18: =SUM(INDEX($B$11:$D$46,MATCH(N18,$A$11:$A$46,0),0)) -> 0 | P18: 37000000 | R18: Chi phí cảng dỡ | S18: 0 | T18: =SUM(INDEX($B$11:$D$46,MATCH(S18,$A$11:$A$46,0),0)) -> 0 | U18: 37000000
A19: Sơn Dương | B19: 45000000 | H19: Dầu DO | J19: =+K14*VLOOKUP(J$10,A$1:G$6,6,FALSE)*17000 -> 238680000 | M19: Dầu DO | O19: =+P14*$F$5*20000 -> 391680000 | R19: Dầu DO | T19: =+U14*$F$5*20000 -> 473280000
A20: Hòn La | C20: 45000000 | H20: Dầu LO | J20: 10000000 | M20: Dầu LO | O20: 10000000 | R20: Dầu LO | T20: 10000000
A21: Chân Mây | C21: 40000000 | H21: VAT | J21: =+J13*0.08 -> 47704800 | M21: VAT | O21: =+O13*0.08 -> 69120000 | R21: VAT | T21: =+T13*0.08 -> 45312000
A22: Đà Nẵng | C22: 32000000 | H22: Chi Phí | J22: =+SUM(J15:J21)+K17+K18 -> 4.9348574e+08 | M22: Chi Phí | O22: =+SUM(O15:O21)+P17+P18 -> 6.4691111e+08 | R22: Chi Phí | T22: =+SUM(T15:T21)+U17+U18 -> 7.2492533e+08
A23: Dung Quất | C23: 40000000 | H23: Lợi nhuận | J23: =+J13-J22 -> 1.0282426e+08 | M23: Lợi nhuận | O23: =+O13-O22 -> 2.1708889e+08 | R23: Lợi nhuận | T23: =+T13-T22 -> -1.5852533e+08
A24: Quy Nhơn | C24: 35000000
A25: Cam Ranh | C25: 40000000
A26: Vĩnh Tân | B26: 35000000
A27: Vũng Tàu | B27: 37000000
A28: HCM | B28: 37000000
A29: Long An | B29: 35000000
A30: Trà Vinh | B30: 37000000
A31: Cần Thơ | B31: 38000000
A32: An Giang/Gạo | B32: 38000000
A33: Vĩnh Xương | B33: 68550000

Sheet T10-2025
AB1: =+IF(U1="Cty Ngọc Anh",J1, "") | AC1: =+IF(V1="Cty Ngọc Anh",K1, "") | AE1: =+IF($V1="Cty Hoàng Quyên",$K1, "") | AF1: =+IF($V1="Cty Hoàng Long",$K1, "") | AG1: =+IF($V1="Cty An Hưng",$K1, "") | AH1: =+IF($V1="Cty An Hưng",$K1, "") | AI1: =+IF($V1="Cty An Hưng",$K1, "") | AJ1: =+IF($V1="Cty Thành Năm",$K1, "") | AK1: =+IF($V1="Cty Tân Hoàng Đạt",$K1, "") | AL1: =+IF($V1="Cty Thái Bình Dương",$K1, "") | AM1: =+IF($V1="Cty Việt Anh",$K1, "") | AN1: =+IF($V1="Cty Thành Công",$K1, "") | AO1: =+IF($V1="Cty Sông Hậu",$K1, "") | AP1: =+IF($V1="Cty Hằng Phát",$K1, "")
B2: KẾT QUẢ KINH DOANH KHAI THÁC | AM2: =+IF($V2="Cty Việt Anh",$K2, "") | AN2: =+IF($V2="Cty Thành Công",$K2, "") | AO2: =+IF($V2="Cty Sông Hậu",$K2, "") | AP2: =+IF($V2="Cty Hằng Phát",$K2, "")
B4: Doanh thu | W4: Chi phí | AN4: =+IF($V4="Cty Thành Công",$K4, "") | AO4: =+IF($V4="Cty Sông Hậu",$K4, "") | AP4: =+IF($V4="Cty Hằng Phát",$K4, "")
A5: Tháng | B5: Tên tàu | C5: Chuyến | D5: Tên hàng | E5: Ngày xếp | F5: Cảng xếp | G5: Ngày dỡ | H5: Cảng dỡ | I5: Khối lượng tính cước | J5: Thực tế (Đơn giá đã có VAT ) | K5: Thành tiền | L5: Số hóa đơn | M5: Ngày xuất hoá đơn | N5: Tiền gửi | O5: Hóa đơn (Giá chưa VAT /1.08) | P5: Thành tiền2 | Q5: VAT 8% | R5: Tổng cộng | S5: Chênh lệch sau thuế | T5: Thuế gửi | U5: Số tiền phải trả gửi giá | V5: Đơn vị | W5: Đại lý cảng xếp | X5: Đại lý cảng dỡ | Y5: Tàu chi cảng xếp | Z5: Tàu chi cảng dỡ | AA5: Hoa Tiêu | AB5: Tàu lai dắt | AC5: Phí cầu bến | AD5: Tiền Bông | AE5: Dầu DO | AF5: Dầu LO | AG5: Tiền lương | AH5: Tiền VAT | AI5: Bảo hiểm | AJ5: Tiền ăn uống | AK5: Vật tư (Công ty cấp) | AL5: Vật tư (Tàu chi) | AM5: Chi phí khác | AN5: Tổng cộng chi phí | AO5: =+IF($V5="Cty Sông Hậu",$K5, "") | AP5: =+IF($V5="Cty Hằng Phát",$K5, "")
I6: 1 | J6: 2 | K6: (3=1*2) | L6: 4 | N6: 5 | O6: 6 | P6: (7=1*6) | Q6: (8=7*8%) | R6: (9=7+8) | S6: (10=9-3) | T6: (11=10/1.08*tỉ lệ thuế gửi) | U6: (12=10-11) | AB6: =+IF(U6="Cty Ngọc Anh",J6, "") | AC6: =+IF(V6="Cty Ngọc Anh",K6, "") | AE6: =+IF($V6="Cty Hoàng Quyên",$K6, "") | AF6: =+IF($V6="Cty Hoàng Long",$K6, "") | AG6: =+IF($V6="Cty An Hưng",$K6, "") | AH6: =+IF($V6="Cty An Hưng",$K6, "") | AI6: =+IF($V6="Cty An Hưng",$K6, "") | AJ6: =+IF($V6="Cty Thành Năm",$K6, "") | AK6: =+IF($V6="Cty Tân Hoàng Đạt",$K6, "") | AL6: =+IF($V6="Cty Thái Bình Dương",$K6, "") | AM6: =+IF($V6="Cty Việt Anh",$K6, "") | AN6: =+IF($V6="Cty Thành Công",$K6, "") | AO6: 45932.562 | AP6: 45940.812 | AQ6: =++AP6-AO6 -> 8.25 | AR6: =+AJ6/31*AQ6 -> #VALUE! | AS6: =+AG6/31*AQ6 -> #VALUE! | AT6: =+AI6/31*AQ6 -> #VALUE!
A7: {=+_xlfn._xlws.FILTER('So lieu khai thac'!A5:AT417,'So lieu khai thac'!A5:A417=10,"")}
B23: Tổng hợp kết quả kinh doanh tháng 11
B26: Tàu | C26: VG05 | E26: Tàu | F26: VG09 | H26: Tàu | I26: VG15 | K26: Tàu | L26: VG18 | N26: Tàu | O26: VG36
B27: Số chuyến | C27: =+COUNTIF($B$7:$B$24,C$26) -> 0 | E27: Số chuyến | F27: =+COUNTIF($B$7:$B$24,F$26) -> 0 | H27: Số chuyến | I27: =+COUNTIF($B$7:$B$24,I$26) -> 0 | K27: Số chuyến | L27: =+COUNTIF($B$7:$B$24,L$26) -> 0 | N27: Số chuyến | O27: =+COUNTIF($B$7:$B$24,O$26) -> 0
B28: Doanh thu | C28: =+SUMIF($B$7:$B$24,C26,$K$7:$K$24) -> 0 | E28: Doanh thu | F28: =+SUMIF($B$7:$B$24,F26,$K$7:$K$24) -> 0 | H28: Doanh thu | I28: =+SUMIF($B$7:$B$24,I26,$K$7:$K$24) -> 0 | K28: Doanh thu | L28: =+SUMIF($B$7:$B$24,L26,$K$7:$K$24) -> 0 | N28: Doanh thu | O28: =+SUMIF($B$7:$B$24,O26,$K$7:$K$24) -> 0
B29: Chi Phí | C29: =+SUMIF($B$7:$B$24,C26,$AN$7:$AN$24) -> 0 | E29: Chi Phí | F29: =+SUMIF($B$7:$B$24,F26,$AN$7:$AN$24) -> 0 | H29: Chi Phí | I29: =+SUMIF($B$7:$B$24,I26,$AN$7:$AN$24) -> 0 | K29: Chi Phí | L29: =+SUMIF($B$7:$B$24,L26,$AN$7:$AN$24) -> 0 | N29: Chi Phí | O29: =+SUMIF($B$7:$B$24,O26,$AN$7:$AN$24) -> 0
B30: Lợi nhuận | C30: =+C28-C29 -> 0 | E30: Lợi nhuận | F30: =+F28-F29 -> 0 | H30: Lợi nhuận | I30: =+I28-I29 -> 0 | K30: Lợi nhuận | L30: =+L28-L29 -> 0 | N30: Lợi nhuận | O30: =+O28-O29 -> 0
E32: Doanh thu tổng hợp | G32: =+C28+F28+I28+L28+O28 -> 0
E33: Chi phí tổng hợp | G33: =+C29+F29+I29+L29+O29 -> 0
E34: Lợi nhuận tổng hợp | G34: =+C30+F30+I30+L30+O30 -> 0

Sheet T11-2025
AB1: =+IF(U1="Cty Ngọc Anh",J1, "") | AC1: =+IF(V1="Cty Ngọc Anh",K1, "") | AE1: =+IF($V1="Cty Hoàng Quyên",$K1, "") | AF1: =+IF($V1="Cty Hoàng Long",$K1, "") | AG1: =+IF($V1="Cty An Hưng",$K1, "") | AH1: =+IF($V1="Cty An Hưng",$K1, "") | AI1: =+IF($V1="Cty An Hưng",$K1, "") | AJ1: =+IF($V1="Cty Thành Năm",$K1, "") | AK1: =+IF($V1="Cty Tân Hoàng Đạt",$K1, "") | AL1: =+IF($V1="Cty Thái Bình Dương",$K1, "") | AM1: =+IF($V1="Cty Việt Anh",$K1, "") | AN1: =+IF($V1="Cty Thành Công",$K1, "") | AO1: =+IF($V1="Cty Sông Hậu",$K1, "") | AP1: =+IF($V1="Cty Hằng Phát",$K1, "")
B2: KẾT QUẢ KINH DOANH KHAI THÁC | AM2: =+IF($V2="Cty Việt Anh",$K2, "") | AN2: =+IF($V2="Cty Thành Công",$K2, "") | AO2: =+IF($V2="Cty Sông Hậu",$K2, "") | AP2: =+IF($V2="Cty Hằng Phát",$K2, "")
B4: Doanh thu | W4: Chi phí | AN4: =+IF($V4="Cty Thành Công",$K4, "") | AO4: =+IF($V4="Cty Sông Hậu",$K4, "") | AP4: =+IF($V4="Cty Hằng Phát",$K4, "")
A5: Tháng | B5: Tên tàu | C5: Chuyến | D5: Tên hàng | E5: Ngày xếp | F5: Cảng xếp | G5: Ngày dỡ | H5: Cảng dỡ | I5: Khối lượng tính cước | J5: Thực tế (Đơn giá đã có VAT ) | K5: Thành tiền | L5: Số hóa đơn | M5: Ngày xuất hoá đơn | N5: Tiền gửi | O5: Hóa đơn (Giá chưa VAT /1.08) | P5: Thành tiền2 | Q5: VAT 8% | R5: Tổng cộng | S5: Chênh lệch sau thuế | T5: Thuế gửi | U5: Số tiền phải trả gửi giá | V5: Đơn vị | W5: Đại lý cảng xếp | X5: Đại lý cảng dỡ | Y5: Tàu chi cảng xếp | Z5: Tàu chi cảng dỡ | AA5: Hoa Tiêu | AB5: Tàu lai dắt | AC5: Phí cầu bến | AD5: Tiền Bông | AE5: Dầu DO | AF5: Dầu LO | AG5: Tiền lương | AH5: Tiền VAT | AI5: Bảo hiểm | AJ5: Tiền ăn uống | AK5: Vật tư (Công ty cấp) | AL5: Vật tư (Tàu chi) | AM5: Chi phí khác | AN5: Tổng cộng chi phí | AO5: =+IF($V5="Cty Sông Hậu",$K5, "") | AP5: =+IF($V5="Cty Hằng Phát",$K5, "")
I6: 1 | J6: 2 | K6: (3=1*2) | L6: 4 | N6: 5 | O6: 6 | P6: (7=1*6) | Q6: (8=7*8%) | R6: (9=7+8) | S6: (10=9-3) | T6: (11=10/1.08*tỉ lệ thuế gửi) | U6: (12=10-11) | AB6: =+IF(U6="Cty Ngọc Anh",J6, "") | AC6: =+IF(V6="Cty Ngọc Anh",K6, "") | AE6: =+IF($V6="Cty Hoàng Quyên",$K6, "") | AF6: =+IF($V6="Cty Hoàng Long",$K6, "") | AG6: =+IF($V6="Cty An Hưng",$K6, "") | AH6: =+IF($V6="Cty An Hưng",$K6, "") | AI6: =+IF($V6="Cty An Hưng",$K6, "") | AJ6: =+IF($V6="Cty Thành Năm",$K6, "") | AK6: =+IF($V6="Cty Tân Hoàng Đạt",$K6, "") | AL6: =+IF($V6="Cty Thái Bình Dương",$K6, "") | AM6: =+IF($V6="Cty Việt Anh",$K6, "") | AN6: =+IF($V6="Cty Thành Công",$K6, "") | AO6: 45932.562 | AP6: 45940.812 | AQ6: =++AP6-AO6 -> 8.25 | AR6: =+AJ6/31*AQ6 -> #VALUE! | AS6: =+AG6/31*AQ6 -> #VALUE! | AT6: =+AI6/31*AQ6 -> #VALUE!
A7: {=+_xlfn._xlws.FILTER('So lieu khai thac'!A5:AT417,'So lieu khai thac'!A5:A417=11,"")}
B23: Tổng hợp kết quả kinh doanh tháng 11
B26: Tàu | C26: VG05 | E26: Tàu | F26: VG09 | H26: Tàu | I26: VG15 | K26: Tàu | L26: VG18 | N26: Tàu | O26: VG36
B27: Số chuyến | C27: =+COUNTIF($B$7:$B$24,C$26) -> 0 | E27: Số chuyến | F27: =+COUNTIF($B$7:$B$24,F$26) -> 0 | H27: Số chuyến | I27: =+COUNTIF($B$7:$B$24,I$26) -> 0 | K27: Số chuyến | L27: =+COUNTIF($B$7:$B$24,L$26) -> 0 | N27: Số chuyến | O27: =+COUNTIF($B$7:$B$24,O$26) -> 0
B28: Doanh thu | C28: =+SUMIF($B$7:$B$24,C26,$K$7:$K$24) -> 0 | E28: Doanh thu | F28: =+SUMIF($B$7:$B$24,F26,$K$7:$K$24) -> 0 | H28: Doanh thu | I28: =+SUMIF($B$7:$B$24,I26,$K$7:$K$24) -> 0 | K28: Doanh thu | L28: =+SUMIF($B$7:$B$24,L26,$K$7:$K$24) -> 0 | N28: Doanh thu | O28: =+SUMIF($B$7:$B$24,O26,$K$7:$K$24) -> 0
B29: Chi Phí | C29: =+SUMIF($B$7:$B$24,C26,$AN$7:$AN$24) -> 0 | E29: Chi Phí | F29: =+SUMIF($B$7:$B$24,F26,$AN$7:$AN$24) -> 0 | H29: Chi Phí | I29: =+SUMIF($B$7:$B$24,I26,$AN$7:$AN$24) -> 0 | K29: Chi Phí | L29: =+SUMIF($B$7:$B$24,L26,$AN$7:$AN$24) -> 0 | N29: Chi Phí | O29: =+SUMIF($B$7:$B$24,O26,$AN$7:$AN$24) -> 0
B30: Lợi nhuận | C30: =+C28-C29 -> 0 | E30: Lợi nhuận | F30: =+F28-F29 -> 0 | H30: Lợi nhuận | I30: =+I28-I29 -> 0 | K30: Lợi nhuận | L30: =+L28-L29 -> 0 | N30: Lợi nhuận | O30: =+O28-O29 -> 0
E32: Doanh thu tổng hợp | G32: =+C28+F28+I28+L28+O28 -> 0
E33: Chi phí tổng hợp | G33: =+C29+F29+I29+L29+O29 -> 0
E34: Lợi nhuận tổng hợp | G34: =+C30+F30+I30+L30+O30 -> 0

Sheet T12-2025
AB1: =+IF(U1="Cty Ngọc Anh",J1, "") | AC1: =+IF(V1="Cty Ngọc Anh",K1, "") | AE1: =+IF($V1="Cty Hoàng Quyên",$K1, "") | AF1: =+IF($V1="Cty Hoàng Long",$K1, "") | AG1: =+IF($V1="Cty An Hưng",$K1, "") | AH1: =+IF($V1="Cty An Hưng",$K1, "") | AI1: =+IF($V1="Cty An Hưng",$K1, "") | AJ1: =+IF($V1="Cty Thành Năm",$K1, "") | AK1: =+IF($V1="Cty Tân Hoàng Đạt",$K1, "") | AL1: =+IF($V1="Cty Thái Bình Dương",$K1, "") | AM1: =+IF($V1="Cty Việt Anh",$K1, "") | AN1: =+IF($V1="Cty Thành Công",$K1, "") | AO1: =+IF($V1="Cty Sông Hậu",$K1, "") | AP1: =+IF($V1="Cty Hằng Phát",$K1, "")
B2: KẾT QUẢ KINH DOANH KHAI THÁC | AM2: =+IF($V2="Cty Việt Anh",$K2, "") | AN2: =+IF($V2="Cty Thành Công",$K2, "") | AO2: =+IF($V2="Cty Sông Hậu",$K2, "") | AP2: =+IF($V2="Cty Hằng Phát",$K2, "")
B4: Doanh thu | W4: Chi phí | AN4: =+IF($V4="Cty Thành Công",$K4, "") | AO4: =+IF($V4="Cty Sông Hậu",$K4, "") | AP4: =+IF($V4="Cty Hằng Phát",$K4, "")
A5: Tháng | B5: Tên tàu | C5: Chuyến | D5: Tên hàng | E5: Ngày xếp | F5: Cảng xếp | G5: Ngày dỡ | H5: Cảng dỡ | I5: Khối lượng tính cước | J5: Thực tế (Đơn giá đã có VAT ) | K5: Thành tiền | L5: Số hóa đơn | M5: Ngày xuất hoá đơn | N5: Tiền gửi | O5: Hóa đơn (Giá chưa VAT /1.08) | P5: Thành tiền2 | Q5: VAT 8% | R5: Tổng cộng | S5: Chênh lệch sau thuế | T5: Thuế gửi | U5: Số tiền phải trả gửi giá | V5: Đơn vị | W5: Đại lý cảng xếp | X5: Đại lý cảng dỡ | Y5: Tàu chi cảng xếp | Z5: Tàu chi cảng dỡ | AA5: Hoa Tiêu | AB5: Tàu lai dắt | AC5: Phí cầu bến | AD5: Tiền Bông | AE5: Dầu DO | AF5: Dầu LO | AG5: Tiền lương | AH5: Tiền VAT | AI5: Bảo hiểm | AJ5: Tiền ăn uống | AK5: Vật tư (Công ty cấp) | AL5: Vật tư (Tàu chi) | AM5: Chi phí khác | AN5: Tổng cộng chi phí | AO5: =+IF($V5="Cty Sông Hậu",$K5, "") | AP5: =+IF($V5="Cty Hằng Phát",$K5, "")
I6: 1 | J6: 2 | K6: (3=1*2) | L6: 4 | N6: 5 | O6: 6 | P6: (7=1*6) | Q6: (8=7*8%) | R6: (9=7+8) | S6: (10=9-3) | T6: (11=10/1.08*tỉ lệ thuế gửi) | U6: (12=10-11) | AB6: =+IF(U6="Cty Ngọc Anh",J6, "") | AC6: =+IF(V6="Cty Ngọc Anh",K6, "") | AE6: =+IF($V6="Cty Hoàng Quyên",$K6, "") | AF6: =+IF($V6="Cty Hoàng Long",$K6, "") | AG6: =+IF($V6="Cty An Hưng",$K6, "") | AH6: =+IF($V6="Cty An Hưng",$K6, "") | AI6: =+IF($V6="Cty An Hưng",$K6, "") | AJ6: =+IF($V6="Cty Thành Năm",$K6, "") | AK6: =+IF($V6="Cty Tân Hoàng Đạt",$K6, "") | AL6: =+IF($V6="Cty Thái Bình Dương",$K6, "") | AM6: =+IF($V6="Cty Việt Anh",$K6, "") | AN6: =+IF($V6="Cty Thành Công",$K6, "") | AO6: 45932.562 | AP6: 45940.812 | AQ6: =++AP6-AO6 -> 8.25 | AR6: =+AJ6/31*AQ6 -> #VALUE! | AS6: =+AG6/31*AQ6 -> #VALUE! | AT6: =+AI6/31*AQ6 -> #VALUE!
A7: {=+_xlfn._xlws.FILTER('So lieu khai thac'!A5:AT417,'So lieu khai thac'!A5:A417=12,"")}
B23: Tổng hợp kết quả kinh doanh tháng 12
B26: Tàu | C26: VG05 | E26: Tàu | F26: VG09 | H26: Tàu | I26: VG15 | K26: Tàu | L26: VG18 | N26: Tàu | O26: VG36
B27: Số chuyến | C27: =+COUNTIF($B$7:$B$24,C$26) -> 0 | E27: Số chuyến | F27: =+COUNTIF($B$7:$B$24,F$26) -> 0 | H27: Số chuyến | I27: =+COUNTIF($B$7:$B$24,I$26) -> 0 | K27: Số chuyến | L27: =+COUNTIF($B$7:$B$24,L$26) -> 0 | N27: Số chuyến | O27: =+COUNTIF($B$7:$B$24,O$26) -> 0
B28: Doanh thu | C28: =+SUMIF($B$7:$B$24,C26,$K$7:$K$24) -> 0 | E28: Doanh thu | F28: =+SUMIF($B$7:$B$24,F26,$K$7:$K$24) -> 0 | H28: Doanh thu | I28: =+SUMIF($B$7:$B$24,I26,$K$7:$K$24) -> 0 | K28: Doanh thu | L28: =+SUMIF($B$7:$B$24,L26,$K$7:$K$24) -> 0 | N28: Doanh thu | O28: =+SUMIF($B$7:$B$24,O26,$K$7:$K$24) -> 0
B29: Chi Phí | C29: =+SUMIF($B$7:$B$24,C26,$AN$7:$AN$24) -> 0 | E29: Chi Phí | F29: =+SUMIF($B$7:$B$24,F26,$AN$7:$AN$24) -> 0 | H29: Chi Phí | I29: =+SUMIF($B$7:$B$24,I26,$AN$7:$AN$24) -> 0 | K29: Chi Phí | L29: =+SUMIF($B$7:$B$24,L26,$AN$7:$AN$24) -> 0 | N29: Chi Phí | O29: =+SUMIF($B$7:$B$24,O26,$AN$7:$AN$24) -> 0
B30: Lợi nhuận | C30: =+C28-C29 -> 0 | E30: Lợi nhuận | F30: =+F28-F29 -> 0 | H30: Lợi nhuận | I30: =+I28-I29 -> 0 | K30: Lợi nhuận | L30: =+L28-L29 -> 0 | N30: Lợi nhuận | O30: =+O28-O29 -> 0
E32: Doanh thu tổng hợp | G32: =+C28+F28+I28+L28+O28 -> 0
E33: Chi phí tổng hợp | G33: =+C29+F29+I29+L29+O29 -> 0
E34: Lợi nhuận tổng hợp | G34: =+C30+F30+I30+L30+O30 -> 0

Sheet T1-2026
AB1: =+IF(U1="Cty Ngọc Anh",J1, "") | AC1: =+IF(V1="Cty Ngọc Anh",K1, "") | AE1: =+IF($V1="Cty Hoàng Quyên",$K1, "") | AF1: =+IF($V1="Cty Hoàng Long",$K1, "") | AG1: =+IF($V1="Cty An Hưng",$K1, "") | AH1: =+IF($V1="Cty An Hưng",$K1, "") | AI1: =+IF($V1="Cty An Hưng",$K1, "") | AJ1: =+IF($V1="Cty Thành Năm",$K1, "") | AK1: =+IF($V1="Cty Tân Hoàng Đạt",$K1, "") | AL1: =+IF($V1="Cty Thái Bình Dương",$K1, "") | AM1: =+IF($V1="Cty Việt Anh",$K1, "") | AN1: =+IF($V1="Cty Thành Công",$K1, "") | AO1: =+IF($V1="Cty Sông Hậu",$K1, "") | AP1: =+IF($V1="Cty Hằng Phát",$K1, "")
B2: KẾT QUẢ KINH DOANH KHAI THÁC | AM2: =+IF($V2="Cty Việt Anh",$K2, "") | AN2: =+IF($V2="Cty Thành Công",$K2, "") | AO2: =+IF($V2="Cty Sông Hậu",$K2, "") | AP2: =+IF($V2="Cty Hằng Phát",$K2, "")
B4: Doanh thu | W4: Chi phí | AN4: =+IF($V4="Cty Thành Công",$K4, "") | AO4: =+IF($V4="Cty Sông Hậu",$K4, "") | AP4: =+IF($V4="Cty Hằng Phát",$K4, "")
A5: Tháng | B5: Tên tàu | C5: Chuyến | D5: Tên hàng | E5: Ngày xếp | F5: Cảng xếp | G5: Ngày dỡ | H5: Cảng dỡ | I5: Khối lượng tính cước | J5: Thực tế (Đơn giá đã có VAT ) | K5: Thành tiền | L5: Số hóa đơn | M5: Ngày xuất hoá đơn | N5: Tiền gửi | O5: Hóa đơn (Giá chưa VAT /1.08) | P5: Thành tiền2 | Q5: VAT 8% | R5: Tổng cộng | S5: Chênh lệch sau thuế | T5: Thuế gửi | U5: Số tiền phải trả gửi giá | V5: Đơn vị | W5: Đại lý cảng xếp | X5: Đại lý cảng dỡ | Y5: Tàu chi cảng xếp | Z5: Tàu chi cảng dỡ | AA5: Hoa Tiêu | AB5: Tàu lai dắt | AC5: Phí cầu bến | AD5: Tiền Bông | AE5: Dầu DO | AF5: Dầu LO | AG5: Tiền lương | AH5: Tiền VAT | AI5: Bảo hiểm | AJ5: Tiền ăn uống | AK5: Vật tư (Công ty cấp) | AL5: Vật tư (Tàu chi) | AM5: Chi phí khác | AN5: Tổng cộng chi phí | AO5: =+IF($V5="Cty Sông Hậu",$K5, "") | AP5: =+IF($V5="Cty Hằng Phát",$K5, "")
I6: 1 | J6: 2 | K6: (3=1*2) | L6: 4 | N6: 5 | O6: 6 | P6: (7=1*6) | Q6: (8=7*8%) | R6: (9=7+8) | S6: (10=9-3) | T6: (11=10/1.08*tỉ lệ thuế gửi) | U6: (12=10-11) | AB6: =+IF(U6="Cty Ngọc Anh",J6, "") | AC6: =+IF(V6="Cty Ngọc Anh",K6, "") | AE6: =+IF($V6="Cty Hoàng Quyên",$K6, "") | AF6: =+IF($V6="Cty Hoàng Long",$K6, "") | AG6: =+IF($V6="Cty An Hưng",$K6, "") | AH6: =+IF($V6="Cty An Hưng",$K6, "") | AI6: =+IF($V6="Cty An Hưng",$K6, "") | AJ6: =+IF($V6="Cty Thành Năm",$K6, "") | AK6: =+IF($V6="Cty Tân Hoàng Đạt",$K6, "") | AL6: =+IF($V6="Cty Thái Bình Dương",$K6, "") | AM6: =+IF($V6="Cty Việt Anh",$K6, "") | AN6: =+IF($V6="Cty Thành Công",$K6, "") | AO6: 45932.562 | AP6: 45940.812 | AQ6: =++AP6-AO6 -> 8.25 | AR6: =+AJ6/31*AQ6 -> #VALUE! | AS6: =+AG6/31*AQ6 -> #VALUE! | AT6: =+AI6/31*AQ6 -> #VALUE!
A7: {=+_xlfn._xlws.FILTER('So lieu khai thac'!A5:AT417,'So lieu khai thac'!A5:A417=12026,"")} -> 12026 | B7: VG05 | C7: C1 | D7: Cát | E7: 46018 | F7: Vĩnh Xương | G7: 46024 | H7: Đà Nẵng | I7: 3922.05 | J7: 125000 | K7: 490256250 | L7: 2 | M7: 7/1 | N7: 13000 | O7: 127777.78 | P7: 5.0115083e+08 | Q7: 40092067 | R7: 541242900 | S7: 50986650 | T7: 13218761 | U7: 37767889 | V7: Hoàng Quyên | W7: 0 | X7: 541242900 | Y7: 0 | Z7: 0 | AA7: 0 | AB7: 0 | AC7: 9312140 | AD7: 0 | AE7: 2500000 | AF7: 15699000 | AG7: 0 | AH7: 0 | AI7: 0 | AJ7: 11137000 | AK7: 310565000 | AL7: 0 | AM7: 223811168 | AN7: 39220500 | AO7: 10069583 | AP7: 46980000 | AQ7: 14888000 | AR7: 4706000 | AS7: 0 | AT7: 688888391
A8: 12026 | B8: VG05 | C8: C2 | D8: Clinker | E8: 46025 | F8: Chân Mây | G8: 46035 | H8: Hậu Giang | I8: 3987.95 | J8: 160000 | K8: 638072000 | L8: 4 | M8: 16/1 | N8: 0 | O8: 148148.15 | P8: 5.9080741e+08 | Q8: 47264593 | R8: 638072000 | S8: 0 | T8: 0 | U8: 0 | V8: Bình Minh | W8: 0 | X8: 638072000 | Y8: 0 | Z8: 0 | AA8: 0 | AB8: 0 | AC8: 0 | AD8: 8893400 | AE8: 17406000 | AF8: 2000000 | AG8: 0 | AH8: 0 | AI8: 9900000 | AJ8: 7425000 | AK8: 393915500 | AL8: 0 | AM8: 15712000 | AN8: 51045760 | AO8: 0 | AP8: 0 | AQ8: 0 | AR8: 0 | AS8: 0 | AT8: 506297660
A9: 12026 | B9: VG05 | C9: C3 | D9: Cát | E9: 46036 | F9: Vĩnh Xương | G9: 46046 | H9: Đà Nẵng | I9: 3975.02 | J9: 120000 | K9: 477002400 | L9: 11 | M9: 28/1 | N9: 4824.2776 | O9: 115578.03 | P9: 4.59425e+08 | Q9: 36754000 | R9: 4.96179e+08 | S9: 19176600 | T9: 4971711.1 | U9: 14204889 | V9: Hoàng Quyên | W9: 0 | X9: 4.96179e+08 | Y9: 0 | Z9: 0 | AA9: 0 | AB9: 0 | AC9: 9531480 | AD9: 0 | AE9: 2500000 | AF9: 14248000 | AG9: 0 | AH9: 0 | AI9: 0 | AJ9: 11137000 | AK9: 0 | AL9: 0 | AM9: 0 | AN9: 38160192 | AO9: 0 | AP9: 0 | AQ9: 0 | AR9: 0 | AS9: 0 | AT9: 75576672
A10: 12026 | B10: VG05 | C10: C4 | D10: Xỉ | E10: 46047 | F10: Sơn Dương | G10: 46054 | H10: Cần Thơ | I10: 4008 | J10: 223000 | K10: 893784000 | L10: 14 | M10: 0 | N10: 8000 | O10: 213888.89 | P10: 8.5726667e+08 | Q10: 68581333 | R10: 925848000 | S10: 32064000 | T10: 8312888.9 | U10: 23751111 | V10: Ngọc Anh | W10: 0 | X10: 925848000 | Y10: 0 | Z10: 0 | AA10: 0 | AB10: 0 | AC10: 41658617 | AD10: 9820610 | AE10: 2800000 | AF10: 3100000 | AG10: 0 | AH10: 0 | AI10: 0 | AJ10: 7425000 | AK10: 0 | AM10: 0 | AN10: 71502720 | AO10: 0 | AP10: 0 | AQ10: 0 | AR10: 0 | AT10: 136306947
A11: 12026 | B11: VG09 | C11: C1 | D11: Cát | E11: 46021 | F11: Vĩnh Xương | G11: 46037 | H11: Đà Nẵng | I11: 4585.48 | J11: 125000 | K11: 573185000 | L11: 6 | M11: 20/1 | N11: -2705.9108 | O11: 113235.27 | P11: 5.1923806e+08 | Q11: 41539044 | R11: 5.607771e+08 | S11: -12407900 | T11: -3216863 | U11: -9191037 | V11: Hoàng Quyên | W11: 0 | X11: 5.607771e+08 | Y11: 0 | Z11: 0 | AA11: 0 | AB11: 0 | AC11: 57146836 | AD11: 0 | AE11: 4180000 | AF11: 18961000 | AG11: 9979200 | AH11: 0 | AI11: 7779048 | AJ11: 11132000 | AK11: 736178300 | AL11: 0 | AM11: 2.547827e+08 | AN11: 45854800 | AO11: 12061667 | AP11: 53580000 | AQ11: 0 | AR11: 1316000 | AS11: 0 | AT11: 1.2129516e+09
A12: 12026 | B12: VG09 | C12: C2 | D12: Xỉ | E12: 46038 | F12: Sơn Dương | G12: 46046 | H12: HCM | I12: 4695.28 | J12: 180000 | K12: 845150400 | L12: 10 | M12: 26/1 | N12: 10000 | O12: 175925.93 | P12: 8.2602148e+08 | Q12: 66081719 | R12: 892103200 | S12: 46952800 | T12: 12172948 | U12: 34779852 | V12: Ngọc Anh | W12: 0 | X12: 892103200 | Y12: 0 | Z12: 0 | AA12: 0 | AB12: 0 | AC12: 44012220 | AD12: 32791040 | AE12: 5800000 | AF12: 7300000 | AG12: 0 | AH12: 0 | AI12: 0 | AJ12: 5775000 | AK12: 0 | AL12: 0 | AM12: 22816000 | AN12: 67612032 | AO12: 0 | AP12: 0 | AQ12: 0 | AR12: 0 | AS12: 0 | AT12: 186106292
A13: 12026 | B13: VG15 | C13: C1 | D13: Xỉ | E13: 46022 | F13: Sơn Dương | G13: 46028 | H13: Hậu Giang | I13: 4814 | J13: 183000 | K13: 880962000 | L13: 3 | M13: 7/1 | N13: 10000 | O13: 178703.7 | P13: 8.6027963e+08 | Q13: 68822370 | R13: 9.29102e+08 | S13: 48140000 | T13: 12480741 | U13: 35659259 | V13: Ngọc Anh | W13: 0 | X13: 9.29102e+08 | Y13: 0 | Z13: 0 | AA13: 0 | AB13: 0 | AC13: 44773738 | AD13: 35337690 | AE13: 0 | AF13: 4340000 | AG13: 0 | AH13: 0 | AI13: 0 | AJ13: 7425000 | AK13: 377484800 | AM13: 255338967 | AN13: 70476960 | AO13: 11511042 | AP13: 44994000 | AQ13: 79100000 | AR13: 4855000 | AT13: 935637197
A14: 12026 | B14: VG15 | C14: C2 | D14: Cát | E14: 46029 | F14: Vĩnh Xương | G14: 46041 | H14: Đà Nẵng | I14: 4619.23 | J14: 125000 | K14: 577403750 | L14: 8 | M14: 21/1 | N14: 8585.2945 | O14: 123690.09 | P14: 5.7135296e+08 | Q14: 45708237 | R14: 6.170612e+08 | S14: 39657450 | T14: 10281561 | U14: 29375889 | V14: Hoàng Quyên | W14: 0 | X14: 6.170612e+08 | Y14: 0 | Z14: 0 | AA14: 0 | AB14: 0 | AC14: 55058278 | AD14: 0 | AE14: 4470000 | AF14: 19639000 | AG14: 0 | AH14: 0 | AI14: 0 | AJ14: 11132000 | AK14: 0 | AM14: 20000000 | AN14: 46192300 | AO14: 0 | AP14: 0 | AQ14: 0 | AR14: 0 | AT14: 156491578
A15: 12026 | B15: VG15 | C15: C3 | D15: Xỉ | E15: 46042 | F15: Sơn Dương | G15: 46056 | H15: Hậu Giang | I15: 4810 | J15: 193000 | K15: 928330000 | L15: 12 | M15: 0 | N15: 10000 | O15: 187962.96 | P15: 9.0410185e+08 | Q15: 72328148 | R15: 976430000 | S15: 48100000 | T15: 12470370 | U15: 35629630 | V15: Ngọc Anh | W15: 0 | X15: 976430000 | Y15: 0 | Z15: 0 | AA15: 0 | AB15: 0 | AC15: 44454445 | AD15: 38432391 | AE15: 2800000 | AF15: 2490000 | AG15: 0 | AH15: 0 | AI15: 0 | AJ15: 7425000 | AK15: 0 | AL15: 0 | AM15: 45800000 | AN15: 74266400 | AO15: 0 | AP15: 0 | AQ15: 0 | AR15: 0 | AS15: 0 | AT15: 215668236
A16: 12026 | B16: VG36 | C16: C1 | D16: Xỉ | E16: 46018 | F16: Sơn Dương | G16: 46025 | H16: HCM | I16: 4769 | J16: 173000 | K16: 825037000 | L16: 1 | M16: 5/1 | N16: 10000 | O16: 169444.44 | P16: 8.0808056e+08 | Q16: 64646444 | R16: 872727000 | S16: 47690000 | T16: 12364074 | U16: 35325926 | V16: Ngọc Anh | W16: 0 | X16: 872727000 | Y16: 0 | Z16: 0 | AA16: 0 | AB16: 0 | AC16: 44661146 | AD16: 37013258 | AE16: 2800000 | AF16: 10360000 | AG16: 0 | AH16: 0 | AI16: 0 | AJ16: 5500000 | AK16: 505731600 | AL16: 0 | AM16: 229091500 | AN16: 66002960 | AO16: 13653750 | AP16: 37220000 | AQ16: 32940000 | AR16: 0 | AS16: 0 | AT16: 984974214
A17: 12026 | B17: VG36 | C17: C2 | D17: Cát | E17: 46026 | F17: Vĩnh Xương | G17: 46035 | H17: Đà Nẵng | I17: 4586.89 | J17: 130000 | K17: 596295700 | L17: 5 | M17: 16/1 | N17: 2934.5155 | O17: 123087.51 | P17: 5.6458889e+08 | Q17: 45167111 | R17: 609756000 | S17: 13460300 | T17: 3489707.4 | U17: 9970592.6 | V17: Hoàng Quyên | W17: 609756000 | X17: 0 | Y17: 0 | Z17: 0 | AA17: 0 | AB17: 0 | AC17: 68550556 | AD17: 0 | AE17: 6500000 | AF17: 20410000 | AG17: 0 | AH17: 0 | AI17: 0 | AJ17: 11000000 | AK17: 0 | AL17: 0 | AM17: 21664000 | AN17: 47703656 | AO17: 0 | AP17: 0 | AQ17: 0 | AR17: 0 | AS17: 0 | AT17: 175828212
A18: 12026 | B18: VG36 | C18: C3 | D18: Clinker | E18: 46036 | F18: Hòn La | G18: 46045 | H18: Hậu Giang | I18: 4765.3 | J18: 183000 | K18: 872049900 | L18: 9 | M18: 26/1 | N18: 0 | O18: 169444.44 | P18: 8.0745361e+08 | Q18: 64596289 | R18: 872049900 | S18: 0 | T18: 0 | U18: 0 | V18: Hoàng Quyên | W18: 872049900 | X18: 0 | Y18: 0 | Z18: 0 | AA18: 0 | AB18: 0 | AC18: 0 | AD18: 34226090 | AE18: 25920000 | AF18: 3600000 | AG18: 0 | AH18: 0 | AI18: 0 | AJ18: 2770000 | AK18: 0 | AL18: 0 | AM18: 0 | AN18: 69763992 | AO18: 0 | AP18: 0 | AQ18: 0 | AR18: 0 | AS18: 0 | AT18: 136280082
A19: 12026 | B19: VG36 | C19: C4 | D19: Gỗ | E19: 46046 | F19: Cần Thơ | G19: 46059 | H19: Cửa Lò | I19: 1 | J19: 320000000 | K19: 320000000 | L19: 15 | M19: 0 | N19: 0 | O19: 2.962963e+08 | P19: 2.962963e+08 | Q19: 23703704 | R19: 320000000 | S19: 0 | T19: 0 | U19: 0 | V19: Ngọc Anh | W19: 0 | X19: 320000000 | Y19: 0 | Z19: 0 | AA19: 0 | AB19: 0 | AC19: 42729942 | AD19: 0 | AE19: 5700000 | AF19: 24300000 | AG19: 0 | AH19: 0 | AI19: 0 | AJ19: 11000000 | AK19: 562444690 | AL19: 0 | AM19: 229091500 | AN19: 25600000 | AO19: 0 | AP19: 0 | AQ19: 0 | AR19: 0 | AS19: 0 | AT19: 900866132
A20: 12026 | B20: VG18 | C20: C1 | D20: Tro ẩm | E20: 46029 | F20: Vĩnh Tân | G20: 46041 | H20: Nghi Sơn | I20: 7322.56 | J20: 95000 | K20: 695643200 | L20: 7 | M20: 20/1 | N20: 0 | O20: 87962.963 | P20: 6.4411407e+08 | Q20: 51529126 | R20: 6.956432e+08 | S20: 0 | T20: 0 | U20: 0 | V20: Ngọc Anh | W20: 0 | X20: 6.956432e+08 | Y20: 0 | Z20: 0 | AA20: 0 | AB20: 0 | AC20: 51613525 | AD20: 0 | AE20: 5000000 | AF20: 16880000 | AG20: 0 | AH20: 0 | AI20: 0 | AJ20: 11340000 | AK20: 542857140 | AL20: 0 | AM20: 257918500 | AN20: 55651456 | AO20: 0 | AP20: 50860000 | AQ20: 40596896 | AR20: 3760000 | AS20: 0 | AT20: 1036477517
A21: 12026 | B21: VG18 | C21: C2 | D21: Clinker | E21: 46042 | F21: Nghi Sơn | G21: 46055 | H21: Hiệp Phước | I21: 7995.95 | J21: 183000 | K21: 1463258850 | L21: 13 | M21: 0 | N21: 10000 | O21: 178703.7 | P21: 1.4289059e+09 | Q21: 1.1431247e+08 | R21: 1.5432183e+09 | S21: 79959500 | T21: 20730241 | U21: 59229259 | V21: Ngọc Anh | W21: 0 | X21: 1.5432183e+09 | Y21: 0 | Z21: 0 | AA21: 0 | AB21: 0 | AC21: 0 | AD21: 64837024 | AE21: 7250000 | AF21: 4300000 | AG21: 6480000 | AH21: 16848000 | AI21: 22231411 | AJ21: 11340000 | AK21: 0 | AM21: 24096000 | AN21: 117060708 | AO21: 0 | AP21: 0 | AQ21: 0 | AR21: 0 | AT21: 274443143
B29: Tổng hợp kết quả kinh doanh tháng 1/2026
B32: Tàu | C32: VG05 | E32: Tàu | F32: VG09 | H32: Tàu | I32: VG15 | K32: Tàu | L32: VG18 | N32: Tàu | O32: VG36
B33: Số chuyến | C33: =+COUNTIF($B$7:$B$30,C$32) -> 4 | E33: Số chuyến | F33: =+COUNTIF($B$7:$B$30,F$32) -> 2 | H33: Số chuyến | I33: =+COUNTIF($B$7:$B$30,I$32) -> 3 | K33: Số chuyến | L33: =+COUNTIF($B$7:$B$30,L$32) -> 2 | N33: Số chuyến | O33: =+COUNTIF($B$7:$B$30,O$32) -> 4
B34: Doanh thu | C34: =+SUMIF($B$7:$B$30,C32,$K$7:$K$30) -> 2499114650 | E34: Doanh thu | F34: =+SUMIF($B$7:$B$30,F32,$K$7:$K$30) -> 1418335400 | H34: Doanh thu | I34: =+SUMIF($B$7:$B$30,I32,$K$7:$K$30) -> 2386695750 | K34: Doanh thu | L34: =+SUMIF($B$7:$B$30,L32,$K$7:$K$30) -> 2158902050 | N34: Doanh thu | O34: =+SUMIF($B$7:$B$30,O32,$K$7:$K$30) -> 2613382600
B35: Chi Phí | C35: =+SUMIF($B$7:$B$30,C32,$AN$7:$AN$30) -> 199929172 | E35: Chi Phí | F35: =+SUMIF($B$7:$B$30,F32,$AN$7:$AN$30) -> 113466832 | H35: Chi Phí | I35: =+SUMIF($B$7:$B$30,I32,$AN$7:$AN$30) -> 190935660 | K35: Chi Phí | L35: =+SUMIF($B$7:$B$30,L32,$AN$7:$AN$30) -> 172712164 | N35: Chi Phí | O35: =+SUMIF($B$7:$B$30,O32,$AN$7:$AN$30) -> 209070608
B36: Lợi nhuận | C36: =+C34-C35 -> 2299185478 | E36: Lợi nhuận | F36: =+F34-F35 -> 1304868568 | H36: Lợi nhuận | I36: =+I34-I35 -> 2195760090 | K36: Lợi nhuận | L36: =+L34-L35 -> 1986189886 | N36: Lợi nhuận | O36: =+O34-O35 -> 2404311992
E38: Doanh thu tổng hợp | G38: =+C34+F34+I34+L34+O34 -> 11076430450
E39: Chi phí tổng hợp | G39: =+C35+F35+I35+L35+O35 -> 886114436
E40: Lợi nhuận tổng hợp | G40: =+C36+F36+I36+L36+O36 -> 10190316014

Sheet T2-2026
AB1: =+IF(U1="Cty Ngọc Anh",J1, "") | AC1: =+IF(V1="Cty Ngọc Anh",K1, "") | AE1: =+IF($V1="Cty Hoàng Quyên",$K1, "") | AF1: =+IF($V1="Cty Hoàng Long",$K1, "") | AG1: =+IF($V1="Cty An Hưng",$K1, "") | AH1: =+IF($V1="Cty An Hưng",$K1, "") | AI1: =+IF($V1="Cty An Hưng",$K1, "") | AJ1: =+IF($V1="Cty Thành Năm",$K1, "") | AK1: =+IF($V1="Cty Tân Hoàng Đạt",$K1, "") | AL1: =+IF($V1="Cty Thái Bình Dương",$K1, "") | AM1: =+IF($V1="Cty Việt Anh",$K1, "") | AN1: =+IF($V1="Cty Thành Công",$K1, "") | AO1: =+IF($V1="Cty Sông Hậu",$K1, "") | AP1: =+IF($V1="Cty Hằng Phát",$K1, "")
B2: KẾT QUẢ KINH DOANH KHAI THÁC | AM2: =+IF($V2="Cty Việt Anh",$K2, "") | AN2: =+IF($V2="Cty Thành Công",$K2, "") | AO2: =+IF($V2="Cty Sông Hậu",$K2, "") | AP2: =+IF($V2="Cty Hằng Phát",$K2, "")
B4: Doanh thu | W4: Chi phí | AN4: =+IF($V4="Cty Thành Công",$K4, "") | AO4: =+IF($V4="Cty Sông Hậu",$K4, "") | AP4: =+IF($V4="Cty Hằng Phát",$K4, "")
A5: Tháng | B5: Tên tàu | C5: Chuyến | D5: Tên hàng | E5: Ngày xếp | F5: Cảng xếp | G5: Ngày dỡ | H5: Cảng dỡ | I5: Khối lượng tính cước | J5: Thực tế (Đơn giá đã có VAT ) | K5: Thành tiền | L5: Số hóa đơn | M5: Ngày xuất hoá đơn | N5: Tiền gửi | O5: Hóa đơn (Giá chưa VAT /1.08) | P5: Thành tiền2 | Q5: VAT 8% | R5: Tổng cộng | S5: Chênh lệch sau thuế | T5: Thuế gửi | U5: Số tiền phải trả gửi giá | V5: Đơn vị | W5: Đại lý cảng xếp | X5: Đại lý cảng dỡ | Y5: Tàu chi cảng xếp | Z5: Tàu chi cảng dỡ | AA5: Hoa Tiêu | AB5: Tàu lai dắt | AC5: Phí cầu bến | AD5: Tiền Bông | AE5: Dầu DO | AF5: Dầu LO | AG5: Tiền lương | AH5: Tiền VAT | AI5: Bảo hiểm | AJ5: Tiền ăn uống | AK5: Vật tư (Công ty cấp) | AL5: Vật tư (Tàu chi) | AM5: Chi phí khác | AN5: Tổng cộng chi phí | AO5: =+IF($V5="Cty Sông Hậu",$K5, "") | AP5: =+IF($V5="Cty Hằng Phát",$K5, "")
I6: 1 | J6: 2 | K6: (3=1*2) | L6: 4 | N6: 5 | O6: 6 | P6: (7=1*6) | Q6: (8=7*8%) | R6: (9=7+8) | S6: (10=9-3) | T6: (11=10/1.08*tỉ lệ thuế gửi) | U6: (12=10-11) | AB6: =+IF(U6="Cty Ngọc Anh",J6, "") | AC6: =+IF(V6="Cty Ngọc Anh",K6, "") | AE6: =+IF($V6="Cty Hoàng Quyên",$K6, "") | AF6: =+IF($V6="Cty Hoàng Long",$K6, "") | AG6: =+IF($V6="Cty An Hưng",$K6, "") | AH6: =+IF($V6="Cty An Hưng",$K6, "") | AI6: =+IF($V6="Cty An Hưng",$K6, "") | AJ6: =+IF($V6="Cty Thành Năm",$K6, "") | AK6: =+IF($V6="Cty Tân Hoàng Đạt",$K6, "") | AL6: =+IF($V6="Cty Thái Bình Dương",$K6, "") | AM6: =+IF($V6="Cty Việt Anh",$K6, "") | AN6: =+IF($V6="Cty Thành Công",$K6, "") | AO6: 45932.562 | AP6: 45940.812 | AQ6: =++AP6-AO6 -> 8.25 | AR6: =+AJ6/31*AQ6 -> #VALUE! | AS6: =+AG6/31*AQ6 -> #VALUE! | AT6: =+AI6/31*AQ6 -> #VALUE!
A7: {=+_xlfn._xlws.FILTER('So lieu khai thac'!A5:AT417,'So lieu khai thac'!A5:A417=22026,"")} -> 22026 | B7: VG05 | C7: C5 | D7: Cát | E7: 46055 | F7: Cần Thơ | G7: 46066 | H7: Đà Nẵng | I7: 3960.99 | J7: 120000 | K7: 475318800 | L7: 20 | M7: 0 | N7: 15000 | O7: 125000 | P7: 4.9512375e+08 | Q7: 39609900 | R7: 5.3473365e+08 | S7: 59414850 | T7: 15403850 | U7: 44011000 | V7: Hoàng Quyên | W7: 0 | X7: 5.3473365e+08 | Y7: 0 | Z7: 0 | AA7: 0 | AB7: 0 | AC7: 9155745 | AD7: 0 | AE7: 2500000 | AF7: 23647000 | AG7: 0 | AH7: 0 | AI7: 0 | AJ7: 11137000 | AK7: 0 | AM7: 223811168 | AN7: 38025504 | AO7: 10069583 | AP7: 37710000 | AQ7: 41517140 | AR7: 5565000 | AT7: 403138140
A8: 22026 | B8: VG05 | C8: C6 | D8: Cliker | E8: 46067 | F8: Hòn La | G8: 46087 | H8: Cần Thơ | I8: 3999.6 | J8: 200000 | K8: 799920000 | L8: 25 | M8: 0 | N8: 17000 | O8: 200925.93 | P8: 8.0362333e+08 | Q8: 64289867 | R8: 867913200 | S8: 67993200 | T8: 17627867 | U8: 50365333 | V8: Thái Bình Dương | W8: 0 | X8: 867913200 | Y8: 0 | Z8: 0 | AA8: 0 | AB8: 0 | AC8: 11682336 | AD8: 9451720 | AE8: 0 | AF8: 0 | AG8: 0 | AH8: 0 | AI8: 0 | AJ8: 0 | AK8: 0 | AL8: 0 | AM8: 0 | AN8: 63993600 | AO8: 0 | AP8: 0 | AQ8: 0 | AR8: 0 | AS8: 0 | AT8: 85127656
A9: 22026 | B9: VG09 | C9: C3 | D9: Tro ẩm | E9: 46047 | F9: Vĩnh Tân | G9: 46058 | H9: Nghi Sơn | I9: 4576.5 | J9: 95000 | K9: 434767500 | L9: 17 | M9: 0 | N9: 0 | O9: 87962.963 | P9: 402562500 | Q9: 32205000 | R9: 434767500 | S9: 0 | T9: 0 | U9: 0 | V9: Ngọc Anh | W9: 0 | X9: 434767500 | Y9: 0 | Z9: 0 | AA9: 0 | AB9: 0 | AC9: 43024312 | AD9: 0 | AE9: 7400000 | AF9: 12570000 | AG9: 0 | AH9: 0 | AI9: 0 | AJ9: 9900000 | AK9: 355195500 | AL9: 0 | AM9: 2.547827e+08 | AN9: 34781400 | AO9: 12061667 | AP9: 22817000 | AQ9: 7175640 | AR9: 2995000 | AS9: 0 | AT9: 7.6270322e+08
A10: 22026 | B10: VG09 | C10: C4 | D10: Xỉ | E10: 46059 | F10: Sơn Dương | G10: 46080 | H10: Hậu Giang | I10: 4745 | J10: 193000 | K10: 915785000 | L10: 21 | M10: 0 | N10: 10000 | O10: 187962.96 | P10: 8.9188426e+08 | Q10: 71350741 | R10: 963235000 | S10: 47450000 | T10: 12301852 | U10: 35148148 | V10: Ngọc Anh | W10: 0 | X10: 963235000 | Y10: 0 | Z10: 0 | AA10: 0 | AB10: 0 | AC10: 43593515 | AD10: 36923510 | AE10: 30000000 | AF10: 0 | AG10: 0 | AH10: 0 | AI10: 0 | AJ10: 0 | AK10: 0 | AL10: 0 | AM10: 22816000 | AN10: 73262800 | AO10: 0 | AP10: 0 | AQ10: 0 | AR10: 0 | AS10: 0 | AT10: 206595825
